 * Running on http://0.0.0.0:5000/ (Press CTRL+C to quit)
[2018-10-11 19:19:45,088] ERROR in app: Exception on /mine [GET]
Traceback (most recent call last):
  File "/usr/local/lib/python3.6/dist-packages/flask/app.py", line 2292, in wsgi_app
    response = self.full_dispatch_request()
  File "/usr/local/lib/python3.6/dist-packages/flask/app.py", line 1815, in full_dispatch_request
    rv = self.handle_user_exception(e)
  File "/usr/local/lib/python3.6/dist-packages/flask/app.py", line 1718, in handle_user_exception
    reraise(exc_type, exc_value, tb)
  File "/usr/local/lib/python3.6/dist-packages/flask/_compat.py", line 35, in reraise
    raise value
  File "/usr/local/lib/python3.6/dist-packages/flask/app.py", line 1813, in full_dispatch_request
    rv = self.dispatch_request()
  File "/usr/local/lib/python3.6/dist-packages/flask/app.py", line 1799, in dispatch_request
    return self.view_functions[rule.endpoint](**req.view_args)
  File "blockchain.py", line 81, in mine
    proof = blockchain.proof_of_work(last_proof)
  File "blockchain.py", line 57, in proof_of_work
    while self.valid_proof(last_proof, proof) is False:
TypeError: valid_proof() takes 2 positional arguments but 3 were given
127.0.0.1 - - [11/Oct/2018 19:19:45] "GET /mine HTTP/1.1" 500 -
[2018-10-11 19:19:49,840] ERROR in app: Exception on /mine [GET]
Traceback (most recent call last):
  File "/usr/local/lib/python3.6/dist-packages/flask/app.py", line 2292, in wsgi_app
    response = self.full_dispatch_request()
  File "/usr/local/lib/python3.6/dist-packages/flask/app.py", line 1815, in full_dispatch_request
    rv = self.handle_user_exception(e)
  File "/usr/local/lib/python3.6/dist-packages/flask/app.py", line 1718, in handle_user_exception
    reraise(exc_type, exc_value, tb)
  File "/usr/local/lib/python3.6/dist-packages/flask/_compat.py", line 35, in reraise
    raise value
  File "/usr/local/lib/python3.6/dist-packages/flask/app.py", line 1813, in full_dispatch_request
    rv = self.dispatch_request()
  File "/usr/local/lib/python3.6/dist-packages/flask/app.py", line 1799, in dispatch_request
    return self.view_functions[rule.endpoint](**req.view_args)
  File "blockchain.py", line 81, in mine
    proof = blockchain.proof_of_work(last_proof)
  File "blockchain.py", line 57, in proof_of_work
    while self.valid_proof(last_proof, proof) is False:
TypeError: valid_proof() takes 2 positional arguments but 3 were given
127.0.0.1 - - [11/Oct/2018 19:19:49] "GET /mine HTTP/1.1" 500 -
[2018-10-11 19:19:54,206] ERROR in app: Exception on /mine [GET]
Traceback (most recent call last):
  File "/usr/local/lib/python3.6/dist-packages/flask/app.py", line 2292, in wsgi_app
    response = self.full_dispatch_request()
  File "/usr/local/lib/python3.6/dist-packages/flask/app.py", line 1815, in full_dispatch_request
    rv = self.handle_user_exception(e)
  File "/usr/local/lib/python3.6/dist-packages/flask/app.py", line 1718, in handle_user_exception
    reraise(exc_type, exc_value, tb)
  File "/usr/local/lib/python3.6/dist-packages/flask/_compat.py", line 35, in reraise
    raise value
  File "/usr/local/lib/python3.6/dist-packages/flask/app.py", line 1813, in full_dispatch_request
    rv = self.dispatch_request()
  File "/usr/local/lib/python3.6/dist-packages/flask/app.py", line 1799, in dispatch_request
    return self.view_functions[rule.endpoint](**req.view_args)
  File "blockchain.py", line 81, in mine
    proof = blockchain.proof_of_work(last_proof)
  File "blockchain.py", line 57, in proof_of_work
    while self.valid_proof(last_proof, proof) is False:
TypeError: valid_proof() takes 2 positional arguments but 3 were given
127.0.0.1 - - [11/Oct/2018 19:19:54] "GET /mine HTTP/1.1" 500 -
